<?xml version="1.0" ?>
<!-- =================================================================================== -->
<!-- |    This document was autogenerated by xacro from youbot.urdf.xacro              | -->
<!-- |    EDITING THIS FILE BY HAND IS NOT RECOMMENDED                                 | -->
<!-- =================================================================================== -->
<robot name="youbot" xmlns:controller="http://playerstage.sourceforge.net/gazebo/xmlschema/#controller" xmlns:interface="http://playerstage.sourceforge.net/gazebo/xmlschema/#interface" xmlns:sensor="http://playerstage.sourceforge.net/gazebo/xmlschema/#sensor" xmlns:xacro="http://ros.org/wiki/xacro">
  <!-- The following included files set up definitions of parts of the robot body -->
  <!-- misc common stuff? -->
  <!-- youbot base -->
  <!-- youbot plate -->
  <!-- youbot arm -->
  <!-- youbot gripper -->
  <!-- generic simulator_gazebo plugins for starting mechanism control, ros time, ros battery -->
  <gazebo>
    <plugin filename="libgazebo_ros_control.so" name="gazebo_ros_controller">
      <robotParam>youbot_description</robotParam>
    </plugin>
  </gazebo>
  <!-- Now we can start using the macros included above to define the actual youbot -->
  <!-- The first use of a macro.  This one was defined in base.urdf.xacro above.
       A macro like this will expand to a set of link and joint definitions, and to additional
       Gazebo-related extensions (sensor plugins, etc).  The macro takes an argument, name, 
       that equals "base", and uses it to generate names for its component links and joints 
       (e.g., base_link).  The included origin block is also an argument to the macro.  By convention, 
       the origin block defines where the component is w.r.t its parent (in this case the parent 
       is the world frame). For more, see http://www.ros.org/wiki/xacro -->
  <!-- foot for arm-->
  <link name="base_footprint">
    <inertial>
      <mass value="0.0001"/>
      <origin rpy="0 0 0" xyz="0 0 -0.05"/>
      <inertia ixx="1.0" ixy="0.0" ixz="0.0" iyy="1.0" iyz="0.0" izz="1.0"/>
    </inertial>
    <visual>
      <origin rpy="0 0 0" xyz="0 0 0"/>
      <geometry>
        <box size="0.001 0.001 0.001"/>
      </geometry>
    </visual>
    <collision>
      <origin rpy="0 0 0" xyz="0 0 -0.05"/>
      <geometry>
        <box size="0.001 0.001 0.001"/>
      </geometry>
    </collision>
  </link>
  <joint name="base_footprint_joint" type="fixed">
    <origin rpy="0 0 0" xyz="0 0 0"/>
    <child link="base_link"/>
    <parent link="base_footprint"/>
  </joint>
  <link name="base_link">
    <inertial>
      <mass value="22.0"/>
      <origin xyz="0 0 0"/>
      <inertia ixx="5.652232699207" ixy="-0.009719934438" ixz="1.293988226423" iyy="5.669473158652" iyz="-0.007379583694" izz="3.683196351726"/>
    </inertial>
    <visual>
      <origin rpy="0 0 0" xyz="0 0 0"/>
      <geometry>
        <mesh filename="package://youbot_description/meshes/youbot_base/base.dae"/>
      </geometry>
    </visual>
    <collision>
      <origin rpy="0 0 0" xyz="0 0 0"/>
      <geometry>
        <!--<box size="${base_size_x} ${base_size_y} ${base_size_z}" />-->
        <mesh filename="package://youbot_description/meshes/youbot_base/base_convex.dae"/>
      </geometry>
    </collision>
  </link>
  <joint name="caster_joint_fl" type="fixed">
    <origin rpy="0 0 0" xyz="0.228 0.158 -0.034"/>
    <axis xyz="0 0 1"/>
    <parent link="base_link"/>
    <child link="caster_link_fl"/>
  </joint>
  <link name="caster_link_fl">
    <inertial>
      <mass value="0.1"/>
      <origin xyz="0 0 0"/>
      <inertia ixx="0.012411765597" ixy="-0.000711733678" ixz="0.00050272983" iyy="0.015218160428" iyz="-0.000004273467" izz="0.011763977943"/>
    </inertial>
  </link>
  <joint name="wheel_joint_fl" type="continuous">
    <axis xyz="0 1 0"/>
    <limit effort="30" velocity="10"/>
    <origin rpy="0 0 0" xyz="0.0 0.0 0.0"/>
    <parent link="caster_link_fl"/>
    <dynamics damping="1.0" friction="1.0"/>
    <safety_controller k_velocity="10.0"/>
    <child link="wheel_link_fl"/>
  </joint>
  <link name="wheel_link_fl">
    <inertial>
      <mass value="0.4"/>
      <origin xyz="0 0 0"/>
      <inertia ixx="0.012411765597" ixy="-0.000711733678" ixz="0.00050272983" iyy="0.015218160428" iyz="-0.000004273467" izz="0.011763977943"/>
    </inertial>
    <visual>
      <origin rpy="0 0 0" xyz="0 0 0"/>
      <geometry>
        <mesh filename="package://youbot_description/meshes/youbot_base/front-left_wheel.dae"/>
      </geometry>
    </visual>
    <collision>
      <origin rpy="1.570795 0 0" xyz="0 0 0"/>
      <geometry>
        <cylinder length="0.05" radius="0.05"/>
      </geometry>
    </collision>
  </link>
  <joint name="caster_joint_fr" type="fixed">
    <origin rpy="0 0 0" xyz="0.228 -0.158 -0.034"/>
    <axis xyz="0 0 1"/>
    <parent link="base_link"/>
    <child link="caster_link_fr"/>
  </joint>
  <link name="caster_link_fr">
    <inertial>
      <mass value="0.1"/>
      <origin xyz="0 0 0"/>
      <inertia ixx="0.012411765597" ixy="-0.000711733678" ixz="0.00050272983" iyy="0.015218160428" iyz="-0.000004273467" izz="0.011763977943"/>
    </inertial>
  </link>
  <joint name="wheel_joint_fr" type="continuous">
    <axis xyz="0 1 0"/>
    <limit effort="30" velocity="10"/>
    <dynamics damping="1.0" friction="1.0"/>
    <safety_controller k_velocity="10.0"/>
    <origin rpy="0 0 0" xyz="0.0 0.0 0.0"/>
    <parent link="caster_link_fr"/>
    <child link="wheel_link_fr"/>
  </joint>
  <link name="wheel_link_fr">
    <inertial>
      <mass value="0.4"/>
      <origin xyz="0 0 0"/>
      <inertia ixx="0.012411765597" ixy="-0.000711733678" ixz="0.00050272983" iyy="0.015218160428" iyz="-0.000004273467" izz="0.011763977943"/>
    </inertial>
    <visual>
      <origin rpy="0 0 0" xyz="0 0 0"/>
      <geometry>
        <mesh filename="package://youbot_description/meshes/youbot_base/front-right_wheel.dae"/>
      </geometry>
    </visual>
    <collision>
      <origin rpy="1.570795 0 0" xyz="0 0 0"/>
      <geometry>
        <cylinder length="0.05" radius="0.05"/>
      </geometry>
    </collision>
  </link>
  <joint name="caster_joint_bl" type="fixed">
    <origin rpy="0 0 0" xyz="-0.228 0.158 -0.034"/>
    <axis xyz="0 0 1"/>
    <parent link="base_link"/>
    <child link="caster_link_bl"/>
  </joint>
  <link name="caster_link_bl">
    <inertial>
      <mass value="0.1"/>
      <origin xyz="0 0 0"/>
      <inertia ixx="0.012411765597" ixy="-0.000711733678" ixz="0.00050272983" iyy="0.015218160428" iyz="-0.000004273467" izz="0.011763977943"/>
    </inertial>
  </link>
  <joint name="wheel_joint_bl" type="continuous">
    <axis xyz="0 1 0"/>
    <limit effort="10" velocity="10"/>
    <limit effort="30" velocity="10"/>
    <dynamics damping="1.0" friction="1.0"/>
    <safety_controller k_velocity="10.0"/>
    <origin rpy="0 0 0" xyz="0.0 0.0 0.0"/>
    <parent link="caster_link_bl"/>
    <child link="wheel_link_bl"/>
  </joint>
  <link name="wheel_link_bl">
    <inertial>
      <mass value="0.4"/>
      <origin xyz="0 0 0"/>
      <inertia ixx="0.012411765597" ixy="-0.000711733678" ixz="0.00050272983" iyy="0.015218160428" iyz="-0.000004273467" izz="0.011763977943"/>
    </inertial>
    <visual>
      <origin rpy="0 0 0" xyz="0 0 0"/>
      <geometry>
        <mesh filename="package://youbot_description/meshes/youbot_base/back-left_wheel.dae"/>
      </geometry>
    </visual>
    <collision>
      <origin rpy="1.570795 0 0" xyz="0 0 0"/>
      <geometry>
        <cylinder length="0.05" radius="0.05"/>
      </geometry>
    </collision>
  </link>
  <joint name="caster_joint_br" type="fixed">
    <origin rpy="0 0 0" xyz="-0.228 -0.158 -0.034"/>
    <axis xyz="0 0 1"/>
    <parent link="base_link"/>
    <child link="caster_link_br"/>
  </joint>
  <link name="caster_link_br">
    <inertial>
      <mass value="0.1"/>
      <origin xyz="0 0 0"/>
      <inertia ixx="0.012411765597" ixy="-0.000711733678" ixz="0.00050272983" iyy="0.015218160428" iyz="-0.000004273467" izz="0.011763977943"/>
    </inertial>
  </link>
  <joint name="wheel_joint_br" type="continuous">
    <axis xyz="0 1 0"/>
    <limit effort="30" velocity="10"/>
    <dynamics damping="1.0" friction="1.0"/>
    <safety_controller k_velocity="10.0"/>
    <origin rpy="0 0 0" xyz="0.0 0.0 0.0"/>
    <parent link="caster_link_br"/>
    <child link="wheel_link_br"/>
  </joint>
  <link name="wheel_link_br">
    <inertial>
      <mass value="0.4"/>
      <origin xyz="0 0 0"/>
      <inertia ixx="0.012411765597" ixy="-0.000711733678" ixz="0.00050272983" iyy="0.015218160428" iyz="-0.000004273467" izz="0.011763977943"/>
    </inertial>
    <visual>
      <origin rpy="0 0 0" xyz="0 0 0"/>
      <geometry>
        <mesh filename="package://youbot_description/meshes/youbot_base/back-right_wheel.dae"/>
      </geometry>
    </visual>
    <collision>
      <origin rpy="1.570795 0 0" xyz="0 0 0"/>
      <geometry>
        <cylinder length="0.05" radius="0.05"/>
      </geometry>
    </collision>
  </link>
  <joint name="base_laser_front_hokuyo_urg04_laser_joint" type="fixed">
    <axis xyz="0 1 0"/>
    <origin rpy="3.15 3.15 0" xyz="0.3 0 -0.03"/>
    <parent link="base_link"/>
    <child link="base_laser_front_link"/>
  </joint>
  <link name="base_laser_front_link" type="laser">
    <inertial>
      <mass value="0.16"/>
      <origin rpy="0 0 0" xyz="0 0 0"/>
      <inertia ixx="0.1" ixy="0" ixz="0" iyy="0.1" iyz="0" izz="0.1"/>
    </inertial>
    <visual>
      <origin rpy="0 0 0" xyz="0 0 0"/>
      <geometry>
        <mesh filename="package://youbot_description/meshes/sensors/hokuyo.dae"/>
      </geometry>
      <material name="DarkGrey"/>
    </visual>
    <collision>
      <origin rpy="0 0 0" xyz="0 0 0"/>
      <geometry>
        <mesh filename="package://youbot_description/meshes/sensors/hokuyo_convex.dae"/>
      </geometry>
    </collision>
  </link>
  <gazebo reference="base_laser_front_link">
    <sensor name="base_laser_front" type="ray">
      <ray>
        <scan>
          <horizontal>
            <samples>640</samples>
            <resolution>1.0</resolution>
            <min_angle>-89.9544498168</min_angle>
            <max_angle>89.9544498168</max_angle>
          </horizontal>
        </scan>
        <range>
          <min>0.05</min>
          <max>5.6</max>
          <resolution>0.36</resolution>
        </range>
      </ray>
      <plugin filename="libgazebo_ros_laser.so" name="gazebo_ros_base_laser_front_controller">
        <gaussianNoise>0.000</gaussianNoise>
        <alwaysOn>true</alwaysOn>
        <updateRate>10</updateRate>
        <topicName>scan_front</topicName>
        <frameName>/base_laser_front_link</frameName>
        <interface:laser name="gazebo_ros_base_laser_front_iface"/>
      </plugin>
    </sensor>
  </gazebo>
  <gazebo>
    <plugin filename="libgazebo_ros_planar_move.so" name="object_controller">
      <commandTopic>cmd_vel</commandTopic>
      <odometryTopic>odom</odometryTopic>
      <odometryFrame>odom</odometryFrame>
      <odometryRate>20.0</odometryRate>
      <robotBaseFrame>base_footprint</robotBaseFrame>
    </plugin>
  </gazebo>
  <gazebo reference="base_footprint">
    <gravity>true</gravity>
    <selfCollide>true</selfCollide>
  </gazebo>
  <transmission name="wheel_trans_fl">
    <type>transmission_interface/SimpleTransmission</type>
    <joint name="wheel_joint_fl"/>
    <actuator name="wheel_motor_fl">
      <hardwareInterface>EffortJointInterface</hardwareInterface>
      <mechanicalReduction>79.2380952381</mechanicalReduction>
    </actuator>
  </transmission>
  <transmission name="wheel_trans_fr">
    <type>transmission_interface/SimpleTransmission</type>
    <joint name="wheel_joint_fr"/>
    <actuator name="wheel_motor_fr">
      <hardwareInterface>EffortJointInterface</hardwareInterface>
      <mechanicalReduction>79.2380952381</mechanicalReduction>
    </actuator>
  </transmission>
  <transmission name="wheel_trans_bl">
    <type>transmission_interface/SimpleTransmission</type>
    <joint name="wheel_joint_bl"/>
    <actuator name="wheel_motor_bl">
      <hardwareInterface>EffortJointInterface</hardwareInterface>
      <mechanicalReduction>79.2380952381</mechanicalReduction>
    </actuator>
  </transmission>
  <transmission name="wheel_trans_br">
    <type>transmission_interface/SimpleTransmission</type>
    <joint name="wheel_joint_br"/>
    <actuator name="wheel_motor_br">
      <hardwareInterface>EffortJointInterface</hardwareInterface>
      <mechanicalReduction>79.2380952381</mechanicalReduction>
    </actuator>
  </transmission>
  <joint name="plate_joint" type="fixed">
    <origin rpy="0 0 0" xyz="-0.159 0 0.055"/>
    <parent link="base_link"/>
    <child link="plate_link"/>
  </joint>
  <link name="plate_link">
    <inertial>
      <origin rpy="0 0 0" xyz="0 0 -0.025"/>
      <mass value="1"/>
      <inertia ixx="0.01" ixy="0" ixz="0" iyy="0.01" iyz="0" izz="0.01"/>
    </inertial>
    <visual>
      <origin rpy="0 0 0" xyz="0 0 -0.025"/>
      <geometry>
        <mesh filename="package://youbot_description/meshes/youbot_plate/plate.dae"/>
      </geometry>
    </visual>
    <collision>
      <origin rpy="0 0 0" xyz="0 0 -0.025"/>
      <geometry>
        <mesh filename="package://youbot_description/meshes/youbot_plate/plate_convex.dae"/>
      </geometry>
    </collision>
  </link>
  <gazebo reference="plate_link">
    <gravity>true</gravity>
    <selfCollide>false</selfCollide>
  </gazebo>
  <joint name="arm_joint_0" type="fixed">
    <origin rpy="0 0 0" xyz="0.143 0 0.046"/>
    <parent link="base_link"/>
    <child link="arm_link_0"/>
  </joint>
  <link name="arm_link_0">
    <inertial>
      <!--<origin xyz="0.023 0 0.006" rpy="0 0 0"/>-->
      <origin rpy="0 0 0" xyz="0 0 0"/>
      <mass value="0.845"/>
      <inertia ixx="0.01" ixy="0" ixz="0" iyy="0.01" iyz="0" izz="0.01"/>
    </inertial>
    <visual>
      <origin rpy="0 0 0" xyz="0 0 0"/>
      <geometry>
        <mesh filename="package://youbot_description/meshes/youbot_arm/arm0.dae"/>
      </geometry>
    </visual>
    <collision>
      <!--<origin xyz="0.023 0 0.006" rpy="0 0 0"/>-->
      <origin rpy="0 0 0" xyz="0 0 0"/>
      <geometry>
        <mesh filename="package://youbot_description/meshes/youbot_arm/arm0_convex.dae"/>
        <!--<cylinder length="0.078" radius="0.093"/>-->
      </geometry>
    </collision>
  </link>
  <joint name="arm_joint_1" type="revolute">
    <origin rpy="0 0 2.96705722222" xyz="0.024 0 0.115"/>
    <parent link="arm_link_0"/>
    <child link="arm_link_1"/>
    <axis xyz="0 0 -1"/>
    <!--<calibration rising="${arm_1_ref}" falling="${arm_1_ref}"/>-->
    <dynamics damping="1" friction="1"/>
    <!-- damping - N*s/m, N*s*m/rad -->
    <!-- friction - N, N*m -->
    <limit effort="10000.0" lower="0" upper="5.89920788889" velocity="1.570795"/>
    <!--effort - N, N*m-->
    <!--velocity - m/s, rad/s-->
    <safety_controller k_position="20" k_velocity="1.51197323648" soft_lower_limit="0.05" soft_upper_limit="5.84920788889"/>
    <!--k_position N/m, N/rad-->
    <!--k_velocity N*s/m, N*s*m/rad-->
    <!--for details: http://www.ros.org/wiki/pr2_controller_manager/safety_limits-->
  </joint>
  <link name="arm_link_1">
    <inertial>
      <mass value="2.412"/>
      <origin rpy="0 0 0" xyz="0.01489 0.00213 0.00213"/>
      <inertia ixx="0.003863" ixy="-0.000979" ixz="0.000000" iyy="0.006196" iyz="0.000000" izz="0.006369"/>
    </inertial>
    <visual>
      <origin rpy="3.14159 0 0" xyz="0 0 0"/>
      <geometry>
        <mesh filename="package://youbot_description/meshes/youbot_arm/arm1.dae"/>
      </geometry>
    </visual>
    <collision>
      <!--<origin xyz="0 0 -0.003" rpy="0 0 0" />-->
      <origin rpy="3.14159 0 0" xyz="0 0 0"/>
      <geometry>
        <mesh filename="package://youbot_description/meshes/youbot_arm/arm_joint_1_convex.stl"/>
        <!--<cylinder length="0.102" radius="0.080"/>-->
      </geometry>
    </collision>
  </link>
  <joint name="arm_joint_2" type="revolute">
    <origin rpy="0 -1.13446305556 0" xyz="0.033 0 0"/>
    <parent link="arm_link_1"/>
    <child link="arm_link_2"/>
    <axis xyz="0 1 0"/>
    <!--<calibration rising="${arm_2_ref}" falling="${arm_2_ref}"/>-->
    <dynamics damping="1" friction="1"/>
    <limit effort="10000.0" lower="0" upper="2.70525805556" velocity="1.570795"/>
    <safety_controller k_position="20" k_velocity="6.04789294593" soft_lower_limit="0.05" soft_upper_limit="2.65525805556"/>
  </joint>
  <link name="arm_link_2">
    <inertial>
      <mass value="1.155"/>
      <origin rpy="0 0 0" xyz="0.10453 0.0017 -0.00297"/>
      <inertia ixx="0.000823" ixy="0.000000" ixz="-0.000000" iyy="0.004447" iyz="0.000000" izz="0.004439"/>
    </inertial>
    <visual>
      <origin rpy="-1.570795 -1.570795 0" xyz="0 0 0"/>
      <geometry>
        <mesh filename="package://youbot_description/meshes/youbot_arm/arm2.dae"/>
      </geometry>
    </visual>
    <collision>
      <!--<origin xyz="0.001 -0.041 0.074" rpy="0 0 0" />-->
      <origin rpy="-1.570795 -1.570795 0" xyz="0 0 0"/>
      <geometry>
        <mesh filename="package://youbot_description/meshes/youbot_arm/arm_joint_2_convex.stl"/>
        <!--<box size="0.074 0.082 0.222"/>-->
      </geometry>
    </collision>
  </link>
  <joint name="arm_joint_3" type="revolute">
    <origin rpy="0 2.54817855556 0" xyz="0.000 0.000 0.155"/>
    <parent link="arm_link_2"/>
    <child link="arm_link_3"/>
    <axis xyz="0 1 0"/>
    <dynamics damping="1" friction="1"/>
    <limit effort="10000.0" lower="-5.1836235" upper="0" velocity="1.570795"/>
    <safety_controller k_position="20" k_velocity="50" soft_lower_limit="-5.1336235" soft_upper_limit="-0.05"/>
  </joint>
  <link name="arm_link_3">
    <inertial>
      <mass value="0.934"/>
      <origin rpy="0 0 0" xyz="0.0001 0.0967 0.02107"/>
      <inertia ixx="0.002459" ixy="0.000000" ixz="0.000000" iyy="0.002571" iyz="-0.000000" izz="0.000535"/>
    </inertial>
    <visual>
      <origin rpy="1.570795 0 3.14159" xyz="0 0 0"/>
      <geometry>
        <mesh filename="package://youbot_description/meshes/youbot_arm/arm3.dae"/>
      </geometry>
    </visual>
    <collision>
      <!--<origin xyz="0.000 0.025 0.067" rpy="0 0 0" />-->
      <origin rpy="1.570795 0 3.14159" xyz="0 0 0"/>
      <geometry>
        <mesh filename="package://youbot_description/meshes/youbot_arm/arm_joint_3_convex.stl"/>
        <!--<box size="0.064 0.054 0.192"/>-->
      </geometry>
    </collision>
  </link>
  <joint name="arm_joint_4" type="revolute">
    <origin rpy="0 -1.78896097222 0" xyz="0.000 0.000 0.135"/>
    <parent link="arm_link_3"/>
    <child link="arm_link_4"/>
    <axis xyz="0 1 0"/>
    <!--<calibration rising="${arm_4_ref}" falling="${arm_4_ref}"/>-->
    <dynamics damping="1" friction="1"/>
    <limit effort="10000.0" lower="0" upper="3.57792194444" velocity="1.570795"/>
    <safety_controller k_position="20" k_velocity="100" soft_lower_limit="0" soft_upper_limit="3.52792194444"/>
  </joint>
  <link name="arm_link_4">
    <inertial>
      <mass value="0.877"/>
      <origin rpy="0 0 0" xyz="0.00011 0.05103 -0.02319"/>
      <inertia ixx="0.000869" ixy="0.000000" ixz="-0.000000" iyy="0.001173" iyz="-0.000231" izz="0.001091"/>
    </inertial>
    <visual>
      <origin rpy="1.570795 0 3.14159" xyz="0 0 0"/>
      <geometry>
        <mesh filename="package://youbot_description/meshes/youbot_arm/arm4.dae"/>
      </geometry>
    </visual>
    <collision>
      <!--<origin xyz="0 0 0.026" rpy="0 0 0" />-->
      <origin rpy="1.570795 0 3.14159" xyz="0 0 0"/>
      <geometry>
        <mesh filename="package://youbot_description/meshes/youbot_arm/arm_joint_4_convex.stl"/>
        <!--<box size="0.058 0.100 0.118"/>-->
      </geometry>
    </collision>
  </link>
  <joint name="arm_joint_5" type="revolute">
    <origin rpy="0 0 2.92342402778" xyz="0 0 0.114"/>
    <parent link="arm_link_4"/>
    <child link="arm_link_5"/>
    <axis xyz="0 0 -1"/>
    <!--<calibration rising="${arm_5_ref}" falling="${arm_5_ref}"/>-->
    <dynamics damping="1" friction="1"/>
    <limit effort="10000.0" lower="0" upper="5.84684805556" velocity="1.570795"/>
    <safety_controller k_position="20" k_velocity="100" soft_lower_limit="0" soft_upper_limit="5.79684805556"/>
  </joint>
  <link name="arm_link_5">
    <inertial>
      <mass value="0.251"/>
      <origin rpy="0 0 0" xyz="0.0 0.00115 -0.01683"/>
      <inertia ixx="0.000280" ixy="0.000000" ixz="0.000000" iyy="0.000339" iyz="0.000000" izz="0.000119"/>
    </inertial>
    <visual>
      <origin rpy="0 0 0" xyz="0 0 0"/>
      <geometry>
        <mesh filename="package://youbot_description/meshes/youbot_arm/arm5.dae"/>
      </geometry>
    </visual>
    <collision>
      <origin rpy="0 0 0" xyz="0 0 0"/>
      <geometry>
        <mesh filename="package://youbot_description/meshes/youbot_arm/arm_joint_5_convex.stl"/>
        <!--<box size="0.054 0.096 0.030"/>-->
      </geometry>
    </collision>
  </link>
  <gazebo reference="arm_link_0">
    <gravity>true</gravity>
    <selfCollide>true</selfCollide>
  </gazebo>
  <gazebo reference="arm_link_1">
    <gravity>true</gravity>
    <selfCollide>true</selfCollide>
  </gazebo>
  <gazebo reference="arm_link_2">
    <gravity>true</gravity>
    <selfCollide>true</selfCollide>
  </gazebo>
  <gazebo reference="arm_link_3">
    <gravity>true</gravity>
    <selfCollide>true</selfCollide>
  </gazebo>
  <gazebo reference="arm_link_4">
    <gravity>true</gravity>
    <selfCollide>true</selfCollide>
  </gazebo>
  <gazebo reference="arm_link_5">
    <gravity>true</gravity>
    <selfCollide>true</selfCollide>
  </gazebo>
  <transmission name="arm_trans_1">
    <type>transmission_interface/SimpleTransmission</type>
    <joint name="arm_joint_1"/>
    <actuator name="arm_motor_1">
      <hardwareInterface>EffortJointInterface</hardwareInterface>
      <mechanicalReduction>1</mechanicalReduction>
    </actuator>
  </transmission>
  <transmission name="arm_trans_2">
    <type>transmission_interface/SimpleTransmission</type>
    <joint name="arm_joint_2"/>
    <actuator name="arm_motor_2">
      <hardwareInterface>EffortJointInterface</hardwareInterface>
      <mechanicalReduction>1</mechanicalReduction>
    </actuator>
  </transmission>
  <transmission name="arm_trans_3">
    <type>transmission_interface/SimpleTransmission</type>
    <joint name="arm_joint_3"/>
    <actuator name="arm_motor_3">
      <hardwareInterface>EffortJointInterface</hardwareInterface>
      <mechanicalReduction>1</mechanicalReduction>
    </actuator>
  </transmission>
  <transmission name="arm_trans_4">
    <type>transmission_interface/SimpleTransmission</type>
    <joint name="arm_joint_4"/>
    <actuator name="arm_motor_4">
      <hardwareInterface>EffortJointInterface</hardwareInterface>
      <mechanicalReduction>1</mechanicalReduction>
    </actuator>
  </transmission>
  <transmission name="arm_trans_5">
    <type>transmission_interface/SimpleTransmission</type>
    <joint name="arm_joint_5"/>
    <actuator name="arm_motor_5">
      <hardwareInterface>EffortJointInterface</hardwareInterface>
      <mechanicalReduction>1</mechanicalReduction>
    </actuator>
  </transmission>
  <joint name="gripper_palm_joint" type="fixed">
    <origin rpy="0 -1.570795 3.14159" xyz="-0.0027 0 .016"/>
    <parent link="arm_link_5"/>
    <child link="gripper_palm_link"/>
  </joint>
  <link name="gripper_palm_link">
    <inertial>
      <origin rpy="3.14159 -1.570795  0" xyz="0 0 0"/>
      <mass value="0.1"/>
      <inertia ixx="0.01" ixy="0" ixz="0" iyy="0.01" iyz="0" izz="0.01"/>
    </inertial>
    <visual>
      <origin rpy="3.14159 -1.570795 0" xyz="0 0 0"/>
      <geometry>
        <mesh filename="package://youbot_description/meshes/youbot_gripper/palm.dae"/>
      </geometry>
    </visual>
    <collision>
      <origin rpy="3.14159 -1.570795 0" xyz="0 0 0"/>
      <geometry>
        <!--<box size="0.050 0.094 0.054"/>-->
        <mesh filename="package://youbot_description/meshes/youbot_gripper/palm_convex.dae"/>
      </geometry>
    </collision>
  </link>
  <joint name="gripper_finger_joint_l" type="prismatic">
    <origin rpy="0 -1.570795 3.14159" xyz="0.046 0.010 0.003 "/>
    <parent link="gripper_palm_link"/>
    <child link="gripper_finger_link_l"/>
    <axis xyz="0 -1 0"/>
    <dynamics damping="1.0" friction="1.0"/>
    <limit effort="1" lower="0" upper="0.0115" velocity="0.1"/>
    <safety_controller k_position="20" k_velocity="25" soft_lower_limit="0.001" soft_upper_limit="0.011"/>
  </joint>
  <link name="gripper_finger_link_l">
    <inertial>
      <origin rpy="0 0 0" xyz="0 -0.001 0"/>
      <mass value="0.01"/>
      <inertia ixx="0.01" ixy="0" ixz="0" iyy="0.01" iyz="0" izz="0.01"/>
    </inertial>
    <visual>
      <origin rpy="0 0 0" xyz="0 0 0"/>
      <geometry>
        <mesh filename="package://youbot_description/meshes/youbot_gripper/finger.dae"/>
      </geometry>
    </visual>
    <collision>
      <origin rpy="0 0 0" xyz="0 0 0"/>
      <geometry>
        <!--<box size="0.014 0.020 0.046"/>-->
        <mesh filename="package://youbot_description/meshes/youbot_gripper/finger_convex.dae"/>
      </geometry>
    </collision>
  </link>
  <joint name="gripper_finger_joint_r" type="prismatic">
    <origin rpy="0 1.570795 0" xyz="0.046 -0.010 0.003"/>
    <parent link="gripper_palm_link"/>
    <child link="gripper_finger_link_r"/>
    <axis xyz="0 -1 0"/>
    <dynamics damping="1.0" friction="1.0"/>
    <limit effort="1" lower="0" upper="0.0115" velocity="0.1"/>
    <safety_controller k_position="20" k_velocity="25" soft_lower_limit="0.001" soft_upper_limit="0.011"/>
  </joint>
  <link name="gripper_finger_link_r">
    <inertial>
      <origin rpy="0 0 0" xyz="0.000 -0.001 0"/>
      <mass value="0.01"/>
      <inertia ixx="0.01" ixy="0" ixz="0" iyy="0.01" iyz="0" izz="0.01"/>
    </inertial>
    <visual>
      <origin rpy="0 0 0" xyz="0 0 0"/>
      <geometry>
        <mesh filename="package://youbot_description/meshes/youbot_gripper/finger.dae"/>
      </geometry>
    </visual>
    <collision>
      <origin rpy="0 0 0" xyz="0.000 0 0"/>
      <geometry>
        <!--<box size="0.014 0.020 0.046"/>-->
        <mesh filename="package://youbot_description/meshes/youbot_gripper/finger_convex.dae"/>
      </geometry>
    </collision>
  </link>
  <gazebo reference="gripper_palm_link">
    <material>Gazebo/Black</material>
    <gravity>true</gravity>
    <selfCollide>true</selfCollide>
  </gazebo>
  <gazebo reference="gripper_finger_l_link">
    <material>Gazebo/Black</material>
    <gravity>true</gravity>
    <selfCollide>true</selfCollide>
  </gazebo>
  <gazebo reference="gripper_finger_r_link">
    <material>Gazebo/Black</material>
    <gravity>true</gravity>
    <selfCollide>true</selfCollide>
  </gazebo>
  <transmission name="gripper_finger_l_trans">
    <type>transmission_interface/SimpleTransmission</type>
    <joint name="gripper_finger_joint_l"/>
    <actuator name="gripper_finger_l_motor">
      <hardwareInterface>EffortJointInterface</hardwareInterface>
      <mechanicalReduction>1</mechanicalReduction>
    </actuator>
  </transmission>
  <transmission name="gripper_finger_r_trans">
    <type>transmission_interface/SimpleTransmission</type>
    <joint name="gripper_finger_joint_r"/>
    <actuator name="gripper_finger_r_motor">
      <hardwareInterface>EffortJointInterface</hardwareInterface>
      <mechanicalReduction>1</mechanicalReduction>
    </actuator>
  </transmission>
</robot>
